Workbook

Sheet AutoimmuneDiseases
A1: AutoimmuneDiseaseId | B1: DiseaseLabel | C1: IsComplexDisease | D1: Name | E1: RelativePath | F1: CountOfDiseaseStages | G1: CountOfInterventionTargets | H1: DiseaseStages | I1: Treatments | J1: ClinicalPhenotypes | K1: IndividualPredictions | L1: CounterfactualTrajectories | M1: InterventionTargets
A2: sle | B2: Systemic Lupus Erythematosus | C2: TRUE | D2: =B2 -> Systemic Lupus Erythematosus | E2: ="/diseases/" & A2 -> /diseases/sle | F2: =COUNTIFS(DiseaseStages!D2:D999, A2) -> 3 | G2: =COUNTIFS(InterventionTargets!D2:D999, A2) -> 7
A3: ra | B3: Rheumatoid Arthritis | C3: TRUE | D3: =B3 -> Rheumatoid Arthritis | E3: ="/diseases/" & A3 -> /diseases/ra | F3: =COUNTIFS(DiseaseStages!D2:D999, A3) -> 2 | G3: =COUNTIFS(InterventionTargets!D2:D999, A3) -> 0
A4: psa | B4: Psoriatic Arthritis | C4: TRUE | D4: =B4 -> Psoriatic Arthritis | E4: ="/diseases/" & A4 -> /diseases/psa | F4: =COUNTIFS(DiseaseStages!D2:D999, A4) -> 1 | G4: =COUNTIFS(InterventionTargets!D2:D999, A4) -> 4

Sheet DiseaseStages
A1: DiseaseStageId | B1: StageLabel | C1: SortOrder | D1: AutoimmuneDisease | E1: Name | F1: ParentPath | G1: RelativePath | H1: AutoimmuneDiseaseDiseaseLabel | I1: IsPresymptomatic
A2: sle-presymptomatic | B2: Presymptomatic | C2: 1 | D2: sle | E2: =H2 & " — " & B2 -> Systemic Lupus Erythematosus — Presymptomatic | F2: =INDEX(AutoimmuneDiseases!E2:E999, MATCH(D2,AutoimmuneDiseases!A2:A999, 0)) -> /diseases/sle | G2: =F2 & "/stages/" & A2 -> /diseases/sle/stages/sle-presymptomatic | H2: =INDEX(AutoimmuneDiseases!B2:B999, MATCH(D2,AutoimmuneDiseases!A2:A999, 0)) -> Systemic Lupus Erythematosus | I2: =IF(B2 = "Presymptomatic", TRUE(), FALSE()) -> TRUE
A3: sle-active | B3: Active | C3: 2 | D3: sle | E3: =H3 & " — " & B3 -> Systemic Lupus Erythematosus — Active | F3: =INDEX(AutoimmuneDiseases!E2:E999, MATCH(D3,AutoimmuneDiseases!A2:A999, 0)) -> /diseases/sle | G3: =F3 & "/stages/" & A3 -> /diseases/sle/stages/sle-active | H3: =INDEX(AutoimmuneDiseases!B2:B999, MATCH(D3,AutoimmuneDiseases!A2:A999, 0)) -> Systemic Lupus Erythematosus | I3: =IF(B3 = "Presymptomatic", TRUE(), FALSE()) -> FALSE
A4: sle-remission | B4: Remission | C4: 3 | D4: sle | E4: =H4 & " — " & B4 -> Systemic Lupus Erythematosus — Remission | F4: =INDEX(AutoimmuneDiseases!E2:E999, MATCH(D4,AutoimmuneDiseases!A2:A999, 0)) -> /diseases/sle | G4: =F4 & "/stages/" & A4 -> /diseases/sle/stages/sle-remission | H4: =INDEX(AutoimmuneDiseases!B2:B999, MATCH(D4,AutoimmuneDiseases!A2:A999, 0)) -> Systemic Lupus Erythematosus | I4: =IF(B4 = "Presymptomatic", TRUE(), FALSE()) -> FALSE
A5: ra-active | B5: Active | C5: 1 | D5: ra | E5: =H5 & " — " & B5 -> Rheumatoid Arthritis — Active | F5: =INDEX(AutoimmuneDiseases!E2:E999, MATCH(D5,AutoimmuneDiseases!A2:A999, 0)) -> /diseases/ra | G5: =F5 & "/stages/" & A5 -> /diseases/ra/stages/ra-active | H5: =INDEX(AutoimmuneDiseases!B2:B999, MATCH(D5,AutoimmuneDiseases!A2:A999, 0)) -> Rheumatoid Arthritis | I5: =IF(B5 = "Presymptomatic", TRUE(), FALSE()) -> FALSE
A6: ra-remission | B6: Remission | C6: 2 | D6: ra | E6: =H6 & " — " & B6 -> Rheumatoid Arthritis — Remission | F6: =INDEX(AutoimmuneDiseases!E2:E999, MATCH(D6,AutoimmuneDiseases!A2:A999, 0)) -> /diseases/ra | G6: =F6 & "/stages/" & A6 -> /diseases/ra/stages/ra-remission | H6: =INDEX(AutoimmuneDiseases!B2:B999, MATCH(D6,AutoimmuneDiseases!A2:A999, 0)) -> Rheumatoid Arthritis | I6: =IF(B6 = "Presymptomatic", TRUE(), FALSE()) -> FALSE
A7: psa-active | B7: Active | C7: 1 | D7: psa | E7: =H7 & " — " & B7 -> Psoriatic Arthritis — Active | F7: =INDEX(AutoimmuneDiseases!E2:E999, MATCH(D7,AutoimmuneDiseases!A2:A999, 0)) -> /diseases/psa | G7: =F7 & "/stages/" & A7 -> /diseases/psa/stages/psa-active | H7: =INDEX(AutoimmuneDiseases!B2:B999, MATCH(D7,AutoimmuneDiseases!A2:A999, 0)) -> Psoriatic Arthritis | I7: =IF(B7 = "Presymptomatic", TRUE(), FALSE()) -> FALSE

Sheet Tissues
A1: TissueId | B1: TissueLabel | C1: Name | D1: RelativePath | E1: CountOfOmicsAssays | F1: OmicsAssays
A2: blood | B2: Blood | C2: =B2 -> Blood | D2: ="/tissues/" & A2 -> /tissues/blood | E2: =COUNTIFS(OmicsAssays!E2:E999, A2) -> 36
A3: gut | B3: Gut | C3: =B3 -> Gut | D3: ="/tissues/" & A3 -> /tissues/gut | E3: =COUNTIFS(OmicsAssays!E2:E999, A3) -> 0
A4: synovium | B4: Synovium | C4: =B4 -> Synovium | D4: ="/tissues/" & A4 -> /tissues/synovium | E4: =COUNTIFS(OmicsAssays!E2:E999, A4) -> 0
A5: skin | B5: Skin | C5: =B5 -> Skin | D5: ="/tissues/" & A5 -> /tissues/skin | E5: =COUNTIFS(OmicsAssays!E2:E999, A5) -> 0
A6: kidney | B6: Kidney | C6: =B6 -> Kidney | D6: ="/tissues/" & A6 -> /tissues/kidney | E6: =COUNTIFS(OmicsAssays!E2:E999, A6) -> 0

Sheet OmicsModalities
A1: OmicsModalityId | B1: ModalityLabel | C1: IsSingleCell | D1: Name | E1: RelativePath | F1: CountOfOmicsAssays | G1: OmicsAssays
A2: long-read-genomes | B2: Phased Telomere-to-Telomere Long-Read Genomes | C2: FALSE | D2: =B2 -> Phased Telomere-to-Telomere Long-Read Genomes | E2: ="/omics-modalities/" & A2 -> /omics-modalities/long-read-genomes | F2: =COUNTIFS(OmicsAssays!D2:D999, A2) -> 0
A3: rna-seq | B3: RNA-seq | C3: FALSE | D3: =B3 -> RNA-seq | E3: ="/omics-modalities/" & A3 -> /omics-modalities/rna-seq | F3: =COUNTIFS(OmicsAssays!D2:D999, A3) -> 12
A4: single-cell-rna | B4: Single-Cell RNA-seq | C4: TRUE | D4: =B4 -> Single-Cell RNA-seq | E4: ="/omics-modalities/" & A4 -> /omics-modalities/single-cell-rna | F4: =COUNTIFS(OmicsAssays!D2:D999, A4) -> 0
A5: atac-seq | B5: ATAC-seq | C5: FALSE | D5: =B5 -> ATAC-seq | E5: ="/omics-modalities/" & A5 -> /omics-modalities/atac-seq | F5: =COUNTIFS(OmicsAssays!D2:D999, A5) -> 12
A6: proteomics | B6: Proteomics | C6: FALSE | D6: =B6 -> Proteomics | E6: ="/omics-modalities/" & A6 -> /omics-modalities/proteomics | F6: =COUNTIFS(OmicsAssays!D2:D999, A6) -> 12
A7: microbiome | B7: Microbiome | C7: FALSE | D7: =B7 -> Microbiome | E7: ="/omics-modalities/" & A7 -> /omics-modalities/microbiome | F7: =COUNTIFS(OmicsAssays!D2:D999, A7) -> 0
A8: methylome | B8: Methylome (sparse context) | C8: FALSE | D8: =B8 -> Methylome (sparse context) | E8: ="/omics-modalities/" & A8 -> /omics-modalities/methylome | F8: =COUNTIFS(OmicsAssays!D2:D999, A8) -> 0
A9: hi-c | B9: Chromatin Conformation Hi-C (sparse context) | C9: FALSE | D9: =B9 -> Chromatin Conformation Hi-C (sparse context) | E9: ="/omics-modalities/" & A9 -> /omics-modalities/hi-c | F9: =COUNTIFS(OmicsAssays!D2:D999, A9) -> 0

Sheet FederatedDatasets
A1: FederatedDatasetId | B1: NodeLabel | C1: Region | D1: IsPrivacyPreserving | E1: Name | F1: RelativePath | G1: CountOfIndividuals | H1: Individuals | I1: OmicsAssays | J1: CohortReplications
A2: fed-europe | B2: European Reference Node | C2: Europe | D2: TRUE | E2: =B2 -> European Reference Node | F2: ="/datasets/" & A2 -> /datasets/fed-europe | G2: =COUNTIFS(Individuals!G2:G999, A2) -> 4
A3: fed-east-asia | B3: East Asia Federated Node | C3: East Asia | D3: TRUE | E3: =B3 -> East Asia Federated Node | F3: ="/datasets/" & A3 -> /datasets/fed-east-asia | G3: =COUNTIFS(Individuals!G2:G999, A3) -> 1
A4: fed-west-africa | B4: West Africa Federated Node | C4: West Africa | D4: TRUE | E4: =B4 -> West Africa Federated Node | F4: ="/datasets/" & A4 -> /datasets/fed-west-africa | G4: =COUNTIFS(Individuals!G2:G999, A4) -> 1
A5: fed-amazon | B5: Amazon Indigenous Cohort | C5: Amazon Basin | D5: TRUE | E5: =B5 -> Amazon Indigenous Cohort | F5: ="/datasets/" & A5 -> /datasets/fed-amazon | G5: =COUNTIFS(Individuals!G2:G999, A5) -> 4

Sheet VariantTypes
A1: VariantTypeId | B1: TypeLabel | C1: IsRareVariantClass | D1: Name | E1: RelativePath | F1: CountOfGenomicVariants | G1: GenomicVariants
A2: regulatory | B2: Regulatory Variant | C2: TRUE | D2: =B2 -> Regulatory Variant | E2: ="/variant-types/" & A2 -> /variant-types/regulatory | F2: =COUNTIFS(GenomicVariants!D2:D999, A2) -> 12
A3: coding | B3: Coding Variant | C3: FALSE | D3: =B3 -> Coding Variant | E3: ="/variant-types/" & A3 -> /variant-types/coding | F3: =COUNTIFS(GenomicVariants!D2:D999, A3) -> 0
A4: hla-haplotype | B4: HLA Haplotype | C4: FALSE | D4: =B4 -> HLA Haplotype | E4: ="/variant-types/" & A4 -> /variant-types/hla-haplotype | F4: =COUNTIFS(GenomicVariants!D2:D999, A4) -> 0
A5: structural | B5: Structural Variant | C5: TRUE | D5: =B5 -> Structural Variant | E5: ="/variant-types/" & A5 -> /variant-types/structural | F5: =COUNTIFS(GenomicVariants!D2:D999, A5) -> 0
A6: de-novo | B6: De Novo Mutation | C6: TRUE | D6: =B6 -> De Novo Mutation | E6: ="/variant-types/" & A6 -> /variant-types/de-novo | F6: =COUNTIFS(GenomicVariants!D2:D999, A6) -> 0

Sheet Individuals
A1: IndividualId | B1: GivenName | C1: FamilyName | D1: AncestryLabel | E1: AgeYears | F1: IsAncestryAbsentFromTraining | G1: FederatedDataset | H1: EnrollmentDate | I1: HasCrypticRelatednessFlag | J1: Name | K1: Slug | L1: RelativePath | M1: FederatedDatasetNodeLabel | N1: CountOfGenomicVariants | O1: CountOfCausalMechanisms | P1: CountOfEpistaticInteractions | Q1: RareVariantBurdenScore | R1: CausalArchitectureScore | S1: IsDevelopmentWindow | T1: IsAgingWindow | U1: CountConfirmedCausalNodes | V1: SumConfirmedCausalConfidence | W1: CountCrossAncestryConfirmedNodes | X1: MaxSeverityScore | Y1: CountHighSeverityPhenotypes | Z1: HasHighSeverityPhenotype | AA1: CountPredictedTreatmentResponses | AB1: HasPredictedTreatmentResponse | AC1: GenomicVariants | AD1: OmicsAssays | AE1: EnvironmentalExposures | AF1: Treatments | AG1: ClinicalPhenotypes | AH1: CausalMechanisms | AI1: EpistaticInteractions | AJ1: CounterfactualTrajectories | AK1: IndividualPredictions | AL1: CaseNarrative | AM1: CountSerologyPanels | AN1: CountPreNephriticSignaturePanels | AO1: IsInPreNephriticSignatureCluster | AP1: SignatureStrength | AQ1: MaxProgressionStateOrder | AR1: LatestSledaiScore | AS1: NephritisProgressionStateKey | AT1: ActivityTier | AU1: IsHighDiseaseActivity | AV1: IsDiseaseProgressing | AW1: TargetPathwayCode | AX1: TargetPathway | AY1: CurrentProgressionStateId | AZ1: ReachableStatesAhead
A2: ind-a-reyes | B2: Ana | C2: Reyes | D2: European | E2: 34 | F2: FALSE | G2: fed-europe | H2: 45026 | I2: FALSE | J2: =B2 & " " & C2 -> Ana Reyes | K2: =SUBSTITUTE(LOWER(C2 & "-" & B2), " ", "-") -> reyes-ana | L2: ="/intake/new-patient/" & K2 -> /intake/new-patient/reyes-ana | M2: =IF(G2 = "", "", INDEX(FederatedDatasets!B2:B999, MATCH(G2,FederatedDatasets!A2:A999, 0))) -> European Reference Node | N2: =COUNTIFS(GenomicVariants!C2:C999, A2) -> 1 | O2: =COUNTIFS(CausalMechanisms!C2:C999, A2) -> 1 | P2: =COUNTIFS(EpistaticInteractions!C2:C999, A2) -> 1 | Q2: =IF(E2 > 0, N2 / E2, 0) -> 0.029411765 | R2: =O2 * 10 + P2 * 5 + Q2 -> 15.029412 | S2: =IF(E2 <= 25, TRUE(), FALSE()) -> FALSE | T2: =IF(E2 >= 60, TRUE(), FALSE()) -> FALSE | U2: =COUNTIFS(CausalMechanisms!C2:C999, A2,CausalMechanisms!AC2:AC999, TRUE()) -> 1 | V2: =SUMIFS(CausalMechanisms!AA2:AA999,CausalMechanisms!C2:C999, A2,CausalMechanisms!AC2:AC999, TRUE()) -> 0.75833333 | W2: =COUNTIFS(CausalMechanisms!C2:C999, A2,CausalMechanisms!AD2:AD999, TRUE()) -> 1 | X2: =_xlfn.MAXIFS(ClinicalPhenotypes!G2:G999,ClinicalPhenotypes!C2:C999, A2) -> 9 | Y2: =COUNTIFS(ClinicalPhenotypes!C2:C999, A2,ClinicalPhenotypes!N2:N999, TRUE()) -> 1 | Z2: =IF(Y2 >= 1, TRUE(), FALSE()) -> TRUE | AA2: =COUNTIFS(Treatments!C2:C999, A2,Treatments!P2:P999, TRUE()) -> 1 | AB2: =IF(AA2 >= 1, TRUE(), FALSE()) -> TRUE | AL2: Ana Reyes, a 34-year-old woman of European ancestry (cohort is in the training set), presents with photosensitive malar rash, arthralgia, and a positive ANA, raising concern for SLE onset. Family history is notable for lupus in a maternal aunt. Genotyping finds the IRF5 regulatory variant rs2004640 at an allele frequency of 0.006 (rare), and allele-specific expression is present at the locus. Functional workup of the IRF5 -> type-I interferon -> SLE-risk edge returns a cis-eQTL in blood RNA-seq with effect 0.91 (SE 0.20), a caQTL in blood ATAC-seq with effect 0.73 (SE 0.19), and a pQTL in blood proteomics with effect 0.66 (SE 0.20) — three assays across two omics modalities, all ancestry-PC and batch adjusted. The edge replicates with a positive effect sign in an East Asian cohort (p=0.004) and in an African cohort (p=0.013), while a European replication is directionally consistent but not significant (p=0.18). Two ancestry-permutation negative controls collapse to the null (permutation effect 0.012 and 0.028, well inside the +/-0.1 null band). The IL-interferon target is druggable (anifrolumab, anti-IFNAR1), giving a perturbable intervention target. For SLE-onset risk, the model's reliability bins each carry coverage of 29-34 held-out individuals, with observed event rates tracking predicted bands closely (e.g. 0.09 observed at the 0.1 band, 0.88 at the 0.9 band). No cryptic-relatedness or assortative-mating leakage was flagged. | AM2: =COUNTIFS(SerologyObservations!B2:B999, A2) -> 2 | AN2: =COUNTIFS(SerologyObservations!B2:B999, A2,SerologyObservations!Q2:Q999, TRUE()) -> 0 | AO2: =IF(AN2>=1,TRUE(),FALSE()) -> FALSE | AP2: =IF(AN2>=2,2,IF(AN2>=1,1,0)) -> 0 | AQ2: =_xlfn.MAXIFS(SerologyObservations!X2:X999,SerologyObservations!B2:B999, A2) -> 0 | AR2: =_xlfn.MAXIFS(SerologyObservations!V2:V999,SerologyObservations!B2:B999, A2) -> 0 | AS2: =IF(AQ2>=5,"BiopsyIndicated",IF(AQ2>=4,"RenalFlareRisk",IF(AQ2>=3,"EarlyNephritis",IF(AQ2>=2,"SerologicActive","PresymptomaticAutoimmunity")))) -> PresymptomaticAutoimmunity | AT2: =IF(AR2>=12,"High / flare",IF(AR2>=6,"Moderate",IF(AR2>=1,"Mild","Quiescent"))) -> Quiescent | AU2: =IF(AR2>=12,TRUE(),FALSE()) -> FALSE | AV2: =IF(OR(AS2="EarlyNephritis",AS2="RenalFlareRisk",AS2="BiopsyIndicated"),TRUE(),FALSE()) -> FALSE | AW2: =_xlfn.MAXIFS(CausalMechanisms!H2:H999,CausalMechanisms!C2:C999, A2) -> 1 | AX2: =IF(AW2=1,"type-I-IFN",IF(AW2=2,"B-cell/autoantibody",IF(AW2=3,"T-cell-costim",IF(AW2=4,"IL-17/23","")))) -> type-I-IFN | AY2: ="lupus-nephritis-progression--" & LOWER(AS2) -> lupus-nephritis-progression--presymptomaticautoimmunity | AZ2: =INDEX(MachineStates!Q2:Q999, MATCH(AY2,MachineStates!A2:A999, 0)) -> #VALUE!
A3: ind-b-okafor | B3: Bili | C3: Okafor | D3: European | E3: 41 | F3: FALSE | G3: fed-europe | H3: 45058 | I3: FALSE | J3: =B3 & " " & C3 -> Bili Okafor | K3: =SUBSTITUTE(LOWER(C3 & "-" & B3), " ", "-") -> okafor-bili | L3: ="/intake/new-patient/" & K3 -> /intake/new-patient/okafor-bili | M3: =IF(G3 = "", "", INDEX(FederatedDatasets!B2:B999, MATCH(G3,FederatedDatasets!A2:A999, 0))) -> European Reference Node | N3: =COUNTIFS(GenomicVariants!C2:C999, A3) -> 1 | O3: =COUNTIFS(CausalMechanisms!C2:C999, A3) -> 1 | P3: =COUNTIFS(EpistaticInteractions!C2:C999, A3) -> 0 | Q3: =IF(E3 > 0, N3 / E3, 0) -> 0.024390244 | R3: =O3 * 10 + P3 * 5 + Q3 -> 10.02439 | S3: =IF(E3 <= 25, TRUE(), FALSE()) -> FALSE | T3: =IF(E3 >= 60, TRUE(), FALSE()) -> FALSE | U3: =COUNTIFS(CausalMechanisms!C2:C999, A3,CausalMechanisms!AC2:AC999, TRUE()) -> 1 | V3: =SUMIFS(CausalMechanisms!AA2:AA999,CausalMechanisms!C2:C999, A3,CausalMechanisms!AC2:AC999, TRUE()) -> 0.75833333 | W3: =COUNTIFS(CausalMechanisms!C2:C999, A3,CausalMechanisms!AD2:AD999, TRUE()) -> 1 | X3: =_xlfn.MAXIFS(ClinicalPhenotypes!G2:G999,ClinicalPhenotypes!C2:C999, A3) -> 8 | Y3: =COUNTIFS(ClinicalPhenotypes!C2:C999, A3,ClinicalPhenotypes!N2:N999, TRUE()) -> 1 | Z3: =IF(Y3 >= 1, TRUE(), FALSE()) -> TRUE | AA3: =COUNTIFS(Treatments!C2:C999, A3,Treatments!P2:P999, TRUE()) -> 1 | AB3: =IF(AA3 >= 1, TRUE(), FALSE()) -> TRUE | AL3: Bili Okafor, a 41-year-old man of European ancestry (in the training set), presents with serositis, fatigue, and a high-titre ANA suggestive of SLE onset. Genotyping finds the IRF5 regulatory variant rs2004640 at an allele frequency of 0.006 (rare), with allele-specific expression present. The IRF5 -> type-I interferon -> SLE-risk edge is supported by a cis-eQTL in blood RNA-seq with effect 0.84 (SE 0.21), a caQTL in blood ATAC-seq with effect 0.79 (SE 0.20), and a pQTL in blood proteomics with effect 0.58 (SE 0.20), spanning two omics modalities and adjusted for ancestry PCs and batch. It replicates positive in an East Asian cohort (p=0.006) and an African cohort (p=0.017), with a non-significant European replication (p=0.22). Two ancestry-permutation controls collapse to the null (permutation effect 0.015 and 0.024 inside +/-0.1). The interferon target is druggable. The mechanism is as solid as Ana's — but the calibration substrate is thin: this site only accrued coverage of 7-14 held-out individuals per reliability bin, far below the 20-count floor needed to trust the predicted-vs-observed match. No cryptic-relatedness leakage was flagged. | AM3: =COUNTIFS(SerologyObservations!B2:B999, A3) -> 2 | AN3: =COUNTIFS(SerologyObservations!B2:B999, A3,SerologyObservations!Q2:Q999, TRUE()) -> 0 | AO3: =IF(AN3>=1,TRUE(),FALSE()) -> FALSE | AP3: =IF(AN3>=2,2,IF(AN3>=1,1,0)) -> 0 | AQ3: =_xlfn.MAXIFS(SerologyObservations!X2:X999,SerologyObservations!B2:B999, A3) -> 0 | AR3: =_xlfn.MAXIFS(SerologyObservations!V2:V999,SerologyObservations!B2:B999, A3) -> 0 | AS3: =IF(AQ3>=5,"BiopsyIndicated",IF(AQ3>=4,"RenalFlareRisk",IF(AQ3>=3,"EarlyNephritis",IF(AQ3>=2,"SerologicActive","PresymptomaticAutoimmunity")))) -> PresymptomaticAutoimmunity | AT3: =IF(AR3>=12,"High / flare",IF(AR3>=6,"Moderate",IF(AR3>=1,"Mild","Quiescent"))) -> Quiescent | AU3: =IF(AR3>=12,TRUE(),FALSE()) -> FALSE | AV3: =IF(OR(AS3="EarlyNephritis",AS3="RenalFlareRisk",AS3="BiopsyIndicated"),TRUE(),FALSE()) -> FALSE | AW3: =_xlfn.MAXIFS(CausalMechanisms!H2:H999,CausalMechanisms!C2:C999, A3) -> 1 | AX3: =IF(AW3=1,"type-I-IFN",IF(AW3=2,"B-cell/autoantibody",IF(AW3=3,"T-cell-costim",IF(AW3=4,"IL-17/23","")))) -> type-I-IFN | AY3: ="lupus-nephritis-progression--" & LOWER(AS3) -> lupus-nephritis-progression--presymptomaticautoimmunity | AZ3: =INDEX(MachineStates!Q2:Q999, MATCH(AY3,MachineStates!A2:A999, 0)) -> #VALUE!
A4: ind-c-chen | B4: Chen | C4: Wei | D4: East Asian | E4: 47 | F4: FALSE | G4: fed-east-asia | H4: 44805 | I4: FALSE | J4: =B4 & " " & C4 -> Chen Wei | K4: =SUBSTITUTE(LOWER(C4 & "-" & B4), " ", "-") -> wei-chen | L4: ="/intake/new-patient/" & K4 -> /intake/new-patient/wei-chen | M4: =IF(G4 = "", "", INDEX(FederatedDatasets!B2:B999, MATCH(G4,FederatedDatasets!A2:A999, 0))) -> East Asia Federated Node | N4: =COUNTIFS(GenomicVariants!C2:C999, A4) -> 1 | O4: =COUNTIFS(CausalMechanisms!C2:C999, A4) -> 1 | P4: =COUNTIFS(EpistaticInteractions!C2:C999, A4) -> 0 | Q4: =IF(E4 > 0, N4 / E4, 0) -> 0.021276596 | R4: =O4 * 10 + P4 * 5 + Q4 -> 10.021277 | S4: =IF(E4 <= 25, TRUE(), FALSE()) -> FALSE | T4: =IF(E4 >= 60, TRUE(), FALSE()) -> FALSE | U4: =COUNTIFS(CausalMechanisms!C2:C999, A4,CausalMechanisms!AC2:AC999, TRUE()) -> 0 | V4: =SUMIFS(CausalMechanisms!AA2:AA999,CausalMechanisms!C2:C999, A4,CausalMechanisms!AC2:AC999, TRUE()) -> 0 | W4: =COUNTIFS(CausalMechanisms!C2:C999, A4,CausalMechanisms!AD2:AD999, TRUE()) -> 0 | X4: =_xlfn.MAXIFS(ClinicalPhenotypes!G2:G999,ClinicalPhenotypes!C2:C999, A4) -> 9 | Y4: =COUNTIFS(ClinicalPhenotypes!C2:C999, A4,ClinicalPhenotypes!N2:N999, TRUE()) -> 1 | Z4: =IF(Y4 >= 1, TRUE(), FALSE()) -> TRUE | AA4: =COUNTIFS(Treatments!C2:C999, A4,Treatments!P2:P999, TRUE()) -> 0 | AB4: =IF(AA4 >= 1, TRUE(), FALSE()) -> FALSE | AL4: Chen Wei, a 47-year-old woman of East Asian ancestry (in the training set), presents with arthritis, oral ulcers, and anti-dsDNA positivity concerning for SLE onset. Genotyping finds the STAT4 regulatory variant rs7574865 at an allele frequency of 0.008 (rare), with allele-specific expression present. The STAT4 -> Th1/IFN -> SLE-risk edge shows a cis-eQTL in blood RNA-seq with effect 1.02 (SE 0.23), a caQTL in blood ATAC-seq with effect 0.61 (SE 0.20), and a pQTL in blood proteomics with effect 0.55 (SE 0.21), across two modalities, ancestry-PC and batch adjusted. Replication is troubling: the effect is positive in an East Asian cohort (p=0.009) but the SIGN FLIPS to negative in an African cohort (p=0.024), and the European replication is non-significant (p=0.27) — only one concordant cohort. Worse, while one ancestry-permutation control collapses (permutation effect 0.013), a second negative control does NOT collapse: its permutation effect is 0.46, far outside the +/-0.1 null band, so the signal is not separable from permuted noise. Reliability bins carry coverage of 28-32 per bin. No cryptic-relatedness leakage was flagged. | AM4: =COUNTIFS(SerologyObservations!B2:B999, A4) -> 2 | AN4: =COUNTIFS(SerologyObservations!B2:B999, A4,SerologyObservations!Q2:Q999, TRUE()) -> 0 | AO4: =IF(AN4>=1,TRUE(),FALSE()) -> FALSE | AP4: =IF(AN4>=2,2,IF(AN4>=1,1,0)) -> 0 | AQ4: =_xlfn.MAXIFS(SerologyObservations!X2:X999,SerologyObservations!B2:B999, A4) -> 0 | AR4: =_xlfn.MAXIFS(SerologyObservations!V2:V999,SerologyObservations!B2:B999, A4) -> 0 | AS4: =IF(AQ4>=5,"BiopsyIndicated",IF(AQ4>=4,"RenalFlareRisk",IF(AQ4>=3,"EarlyNephritis",IF(AQ4>=2,"SerologicActive","PresymptomaticAutoimmunity")))) -> PresymptomaticAutoimmunity | AT4: =IF(AR4>=12,"High / flare",IF(AR4>=6,"Moderate",IF(AR4>=1,"Mild","Quiescent"))) -> Quiescent | AU4: =IF(AR4>=12,TRUE(),FALSE()) -> FALSE | AV4: =IF(OR(AS4="EarlyNephritis",AS4="RenalFlareRisk",AS4="BiopsyIndicated"),TRUE(),FALSE()) -> FALSE | AW4: =_xlfn.MAXIFS(CausalMechanisms!H2:H999,CausalMechanisms!C2:C999, A4) -> 2 | AX4: =IF(AW4=1,"type-I-IFN",IF(AW4=2,"B-cell/autoantibody",IF(AW4=3,"T-cell-costim",IF(AW4=4,"IL-17/23","")))) -> B-cell/autoantibody | AY4: ="lupus-nephritis-progression--" & LOWER(AS4) -> lupus-nephritis-progression--presymptomaticautoimmunity | AZ4: =INDEX(MachineStates!Q2:Q999, MATCH(AY4,MachineStates!A2:A999, 0)) -> #VALUE!
A5: ind-d-santos | B5: Diego | C5: Santos | D5: European | E5: 29 | F5: FALSE | G5: fed-europe | H5: 45311 | I5: TRUE | J5: =B5 & " " & C5 -> Diego Santos | K5: =SUBSTITUTE(LOWER(C5 & "-" & B5), " ", "-") -> santos-diego | L5: ="/intake/new-patient/" & K5 -> /intake/new-patient/santos-diego | M5: =IF(G5 = "", "", INDEX(FederatedDatasets!B2:B999, MATCH(G5,FederatedDatasets!A2:A999, 0))) -> European Reference Node | N5: =COUNTIFS(GenomicVariants!C2:C999, A5) -> 1 | O5: =COUNTIFS(CausalMechanisms!C2:C999, A5) -> 1 | P5: =COUNTIFS(EpistaticInteractions!C2:C999, A5) -> 0 | Q5: =IF(E5 > 0, N5 / E5, 0) -> 0.034482759 | R5: =O5 * 10 + P5 * 5 + Q5 -> 10.034483 | S5: =IF(E5 <= 25, TRUE(), FALSE()) -> FALSE | T5: =IF(E5 >= 60, TRUE(), FALSE()) -> FALSE | U5: =COUNTIFS(CausalMechanisms!C2:C999, A5,CausalMechanisms!AC2:AC999, TRUE()) -> 1 | V5: =SUMIFS(CausalMechanisms!AA2:AA999,CausalMechanisms!C2:C999, A5,CausalMechanisms!AC2:AC999, TRUE()) -> 0.75833333 | W5: =COUNTIFS(CausalMechanisms!C2:C999, A5,CausalMechanisms!AD2:AD999, TRUE()) -> 1 | X5: =_xlfn.MAXIFS(ClinicalPhenotypes!G2:G999,ClinicalPhenotypes!C2:C999, A5) -> 8 | Y5: =COUNTIFS(ClinicalPhenotypes!C2:C999, A5,ClinicalPhenotypes!N2:N999, TRUE()) -> 1 | Z5: =IF(Y5 >= 1, TRUE(), FALSE()) -> TRUE | AA5: =COUNTIFS(Treatments!C2:C999, A5,Treatments!P2:P999, TRUE()) -> 0 | AB5: =IF(AA5 >= 1, TRUE(), FALSE()) -> FALSE | AL5: Diego Santos, a 29-year-old man of European ancestry (in the training set), presents with nephritis and a malar rash concerning for SLE onset. Genotyping finds the IRF5 regulatory variant rs2004640 at an allele frequency of 0.006 (rare), with allele-specific expression present. The IRF5 -> type-I interferon -> SLE-risk edge is fully supported: a cis-eQTL in blood RNA-seq with effect 0.88 (SE 0.20), a caQTL in blood ATAC-seq with effect 0.95 (SE 0.21), and a pQTL in blood proteomics with effect 0.62 (SE 0.20), across two modalities and adjusted for ancestry PCs and batch. It replicates positive in an East Asian cohort (p=0.003) and an African cohort (p=0.019), with a non-significant European replication (p=0.16). Two ancestry-permutation controls collapse to the null (permutation effect 0.009 and 0.031 inside +/-0.1). The interferon target is druggable, and reliability bins carry coverage of 30-36 per bin. However, sample QC raised a cryptic-relatedness / assortative-mating flag for this participant: kinship estimates indicate undeclared relatives inside the cohort, so the prediction may be confounded by leakage rather than the mechanism alone. | AM5: =COUNTIFS(SerologyObservations!B2:B999, A5) -> 3 | AN5: =COUNTIFS(SerologyObservations!B2:B999, A5,SerologyObservations!Q2:Q999, TRUE()) -> 0 | AO5: =IF(AN5>=1,TRUE(),FALSE()) -> FALSE | AP5: =IF(AN5>=2,2,IF(AN5>=1,1,0)) -> 0 | AQ5: =_xlfn.MAXIFS(SerologyObservations!X2:X999,SerologyObservations!B2:B999, A5) -> 5 | AR5: =_xlfn.MAXIFS(SerologyObservations!V2:V999,SerologyObservations!B2:B999, A5) -> 0 | AS5: =IF(AQ5>=5,"BiopsyIndicated",IF(AQ5>=4,"RenalFlareRisk",IF(AQ5>=3,"EarlyNephritis",IF(AQ5>=2,"SerologicActive","PresymptomaticAutoimmunity")))) -> BiopsyIndicated | AT5: =IF(AR5>=12,"High / flare",IF(AR5>=6,"Moderate",IF(AR5>=1,"Mild","Quiescent"))) -> Quiescent | AU5: =IF(AR5>=12,TRUE(),FALSE()) -> FALSE | AV5: =IF(OR(AS5="EarlyNephritis",AS5="RenalFlareRisk",AS5="BiopsyIndicated"),TRUE(),FALSE()) -> TRUE | AW5: =_xlfn.MAXIFS(CausalMechanisms!H2:H999,CausalMechanisms!C2:C999, A5) -> 2 | AX5: =IF(AW5=1,"type-I-IFN",IF(AW5=2,"B-cell/autoantibody",IF(AW5=3,"T-cell-costim",IF(AW5=4,"IL-17/23","")))) -> B-cell/autoantibody | AY5: ="lupus-nephritis-progression--" & LOWER(AS5) -> lupus-nephritis-progression--biopsyindicated | AZ5: =INDEX(MachineStates!Q2:Q999, MATCH(AY5,MachineStates!A2:A999, 0)) -> #VALUE!
A6: ind-e-mensah | B6: Esi | C6: Mensah | D6: African | E6: 38 | F6: FALSE | G6: fed-west-africa | H6: 45122 | I6: FALSE | J6: =B6 & " " & C6 -> Esi Mensah | K6: =SUBSTITUTE(LOWER(C6 & "-" & B6), " ", "-") -> mensah-esi | L6: ="/intake/new-patient/" & K6 -> /intake/new-patient/mensah-esi | M6: =IF(G6 = "", "", INDEX(FederatedDatasets!B2:B999, MATCH(G6,FederatedDatasets!A2:A999, 0))) -> West Africa Federated Node | N6: =COUNTIFS(GenomicVariants!C2:C999, A6) -> 1 | O6: =COUNTIFS(CausalMechanisms!C2:C999, A6) -> 1 | P6: =COUNTIFS(EpistaticInteractions!C2:C999, A6) -> 0 | Q6: =IF(E6 > 0, N6 / E6, 0) -> 0.026315789 | R6: =O6 * 10 + P6 * 5 + Q6 -> 10.026316 | S6: =IF(E6 <= 25, TRUE(), FALSE()) -> FALSE | T6: =IF(E6 >= 60, TRUE(), FALSE()) -> FALSE | U6: =COUNTIFS(CausalMechanisms!C2:C999, A6,CausalMechanisms!AC2:AC999, TRUE()) -> 0 | V6: =SUMIFS(CausalMechanisms!AA2:AA999,CausalMechanisms!C2:C999, A6,CausalMechanisms!AC2:AC999, TRUE()) -> 0 | W6: =COUNTIFS(CausalMechanisms!C2:C999, A6,CausalMechanisms!AD2:AD999, TRUE()) -> 0 | X6: =_xlfn.MAXIFS(ClinicalPhenotypes!G2:G999,ClinicalPhenotypes!C2:C999, A6) -> 3 | Y6: =COUNTIFS(ClinicalPhenotypes!C2:C999, A6,ClinicalPhenotypes!N2:N999, TRUE()) -> 0 | Z6: =IF(Y6 >= 1, TRUE(), FALSE()) -> FALSE | AA6: =COUNTIFS(Treatments!C2:C999, A6,Treatments!P2:P999, TRUE()) -> 0 | AB6: =IF(AA6 >= 1, TRUE(), FALSE()) -> FALSE | AL6: Esi Mensah, a 38-year-old woman of African ancestry (in the training set), presents with arthralgia and cytopenias concerning for SLE onset. Genotyping finds the CTLA4 enhancer variant rs3087243 at an allele frequency of 0.007 (rare), with allele-specific expression present. The CTLA4 -> T-cell costimulation -> SLE-risk edge is well supported: a cis-eQTL in blood RNA-seq with effect 0.79 (SE 0.21), a caQTL in blood ATAC-seq with effect 0.71 (SE 0.20), and a pQTL in blood proteomics with effect 0.41 (SE 0.20), across two modalities, ancestry-PC and batch adjusted. It replicates positive in an East Asian cohort (p=0.007) and a European cohort (p=0.021), with a non-significant African replication (p=0.19). Two ancestry-permutation controls collapse to the null (permutation effect 0.011 and 0.026 inside +/-0.1), and reliability bins carry coverage of 27-33 per bin. The gap is experimental: no perturbable intervention target has been mapped for this edge — there is no agent or assay that could knock the costimulation node down to test it, so the mechanism is not experimentally falsifiable as stated. | AM6: =COUNTIFS(SerologyObservations!B2:B999, A6) -> 2 | AN6: =COUNTIFS(SerologyObservations!B2:B999, A6,SerologyObservations!Q2:Q999, TRUE()) -> 0 | AO6: =IF(AN6>=1,TRUE(),FALSE()) -> FALSE | AP6: =IF(AN6>=2,2,IF(AN6>=1,1,0)) -> 0 | AQ6: =_xlfn.MAXIFS(SerologyObservations!X2:X999,SerologyObservations!B2:B999, A6) -> 0 | AR6: =_xlfn.MAXIFS(SerologyObservations!V2:V999,SerologyObservations!B2:B999, A6) -> 0 | AS6: =IF(AQ6>=5,"BiopsyIndicated",IF(AQ6>=4,"RenalFlareRisk",IF(AQ6>=3,"EarlyNephritis",IF(AQ6>=2,"SerologicActive","PresymptomaticAutoimmunity")))) -> PresymptomaticAutoimmunity | AT6: =IF(AR6>=12,"High / flare",IF(AR6>=6,"Moderate",IF(AR6>=1,"Mild","Quiescent"))) -> Quiescent | AU6: =IF(AR6>=12,TRUE(),FALSE()) -> FALSE | AV6: =IF(OR(AS6="EarlyNephritis",AS6="RenalFlareRisk",AS6="BiopsyIndicated"),TRUE(),FALSE()) -> FALSE | AW6: =_xlfn.MAXIFS(CausalMechanisms!H2:H999,CausalMechanisms!C2:C999, A6) -> 3 | AX6: =IF(AW6=1,"type-I-IFN",IF(AW6=2,"B-cell/autoantibody",IF(AW6=3,"T-cell-costim",IF(AW6=4,"IL-17/23","")))) -> T-cell-costim | AY6: ="lupus-nephritis-progression--" & LOWER(AS6) -> lupus-nephritis-progression--presymptomaticautoimmunity | AZ6: =INDEX(MachineStates!Q2:Q999, MATCH(AY6,MachineStates!A2:A999, 0)) -> #VALUE!
A7: ind-f-haidar | B7: Faisal | C7: Haidar | D7: Indigenous American | E7: 31 | F7: TRUE | G7: fed-amazon | H7: 45689 | I7: FALSE | J7: =B7 & " " & C7 -> Faisal Haidar | K7: =SUBSTITUTE(LOWER(C7 & "-" & B7), " ", "-") -> haidar-faisal | L7: ="/intake/new-patient/" & K7 -> /intake/new-patient/haidar-faisal | M7: =IF(G7 = "", "", INDEX(FederatedDatasets!B2:B999, MATCH(G7,FederatedDatasets!A2:A999, 0))) -> Amazon Indigenous Cohort | N7: =COUNTIFS(GenomicVariants!C2:C999, A7) -> 1 | O7: =COUNTIFS(CausalMechanisms!C2:C999, A7) -> 1 | P7: =COUNTIFS(EpistaticInteractions!C2:C999, A7) -> 0 | Q7: =IF(E7 > 0, N7 / E7, 0) -> 0.032258065 | R7: =O7 * 10 + P7 * 5 + Q7 -> 10.032258 | S7: =IF(E7 <= 25, TRUE(), FALSE()) -> FALSE | T7: =IF(E7 >= 60, TRUE(), FALSE()) -> FALSE | U7: =COUNTIFS(CausalMechanisms!C2:C999, A7,CausalMechanisms!AC2:AC999, TRUE()) -> 1 | V7: =SUMIFS(CausalMechanisms!AA2:AA999,CausalMechanisms!C2:C999, A7,CausalMechanisms!AC2:AC999, TRUE()) -> 0.85833333 | W7: =COUNTIFS(CausalMechanisms!C2:C999, A7,CausalMechanisms!AD2:AD999, TRUE()) -> 0 | X7: =_xlfn.MAXIFS(ClinicalPhenotypes!G2:G999,ClinicalPhenotypes!C2:C999, A7) -> 2 | Y7: =COUNTIFS(ClinicalPhenotypes!C2:C999, A7,ClinicalPhenotypes!N2:N999, TRUE()) -> 0 | Z7: =IF(Y7 >= 1, TRUE(), FALSE()) -> FALSE | AA7: =COUNTIFS(Treatments!C2:C999, A7,Treatments!P2:P999, TRUE()) -> 0 | AB7: =IF(AA7 >= 1, TRUE(), FALSE()) -> FALSE | AL7: Faisal Haidar, a 31-year-old man of Indigenous American ancestry — an ancestry deliberately HELD OUT of the training set — presents with dactylitis, enthesitis, and nail pitting concerning for psoriatic-arthritis (PsA) onset. Genotyping finds the IL23R regulatory variant rs11209026 at an allele frequency of 0.009 (rare), with allele-specific expression present. The IL23R -> IL-17 axis -> PsA-risk edge is well supported: a cis-eQTL in blood RNA-seq with effect 1.07 (SE 0.20), a caQTL in blood ATAC-seq with effect 0.83 (SE 0.21), and a pQTL in blood proteomics with effect 0.74 (SE 0.20), across two modalities and adjusted for ancestry PCs and batch. The IL-17 target is druggable (secukinumab). Two ancestry-permutation controls collapse to the null (permutation effect 0.008 and 0.022 inside +/-0.1), and reliability bins carry coverage of 30-35 per bin. But every replication of this edge was run in an Indigenous American cohort: p=0.005, p=0.015, and p=0.034, all positive, all in the SAME ancestry. There is no cohort in a DIFFERENT ancestry confirming the effect — so for a patient whose ancestry is absent from training, nothing demonstrates the mechanism transports. No cryptic-relatedness leakage was flagged. | AM7: =COUNTIFS(SerologyObservations!B2:B999, A7) -> 2 | AN7: =COUNTIFS(SerologyObservations!B2:B999, A7,SerologyObservations!Q2:Q999, TRUE()) -> 0 | AO7: =IF(AN7>=1,TRUE(),FALSE()) -> FALSE | AP7: =IF(AN7>=2,2,IF(AN7>=1,1,0)) -> 0 | AQ7: =_xlfn.MAXIFS(SerologyObservations!X2:X999,SerologyObservations!B2:B999, A7) -> 0 | AR7: =_xlfn.MAXIFS(SerologyObservations!V2:V999,SerologyObservations!B2:B999, A7) -> 0 | AS7: =IF(AQ7>=5,"BiopsyIndicated",IF(AQ7>=4,"RenalFlareRisk",IF(AQ7>=3,"EarlyNephritis",IF(AQ7>=2,"SerologicActive","PresymptomaticAutoimmunity")))) -> PresymptomaticAutoimmunity | AT7: =IF(AR7>=12,"High / flare",IF(AR7>=6,"Moderate",IF(AR7>=1,"Mild","Quiescent"))) -> Quiescent | AU7: =IF(AR7>=12,TRUE(),FALSE()) -> FALSE | AV7: =IF(OR(AS7="EarlyNephritis",AS7="RenalFlareRisk",AS7="BiopsyIndicated"),TRUE(),FALSE()) -> FALSE | AW7: =_xlfn.MAXIFS(CausalMechanisms!H2:H999,CausalMechanisms!C2:C999, A7) -> 4 | AX7: =IF(AW7=1,"type-I-IFN",IF(AW7=2,"B-cell/autoantibody",IF(AW7=3,"T-cell-costim",IF(AW7=4,"IL-17/23","")))) -> IL-17/23 | AY7: ="lupus-nephritis-progression--" & LOWER(AS7) -> lupus-nephritis-progression--presymptomaticautoimmunity | AZ7: =INDEX(MachineStates!Q2:Q999, MATCH(AY7,MachineStates!A2:A999, 0)) -> #VALUE!
A8: ind-g-lin | B8: Grace | C8: Lin | D8: Indigenous American | E8: 36 | F8: TRUE | G8: fed-amazon | H8: 45691 | I8: FALSE | J8: =B8 & " " & C8 -> Grace Lin | K8: =SUBSTITUTE(LOWER(C8 & "-" & B8), " ", "-") -> lin-grace | L8: ="/intake/new-patient/" & K8 -> /intake/new-patient/lin-grace | M8: =IF(G8 = "", "", INDEX(FederatedDatasets!B2:B999, MATCH(G8,FederatedDatasets!A2:A999, 0))) -> Amazon Indigenous Cohort | N8: =COUNTIFS(GenomicVariants!C2:C999, A8) -> 1 | O8: =COUNTIFS(CausalMechanisms!C2:C999, A8) -> 1 | P8: =COUNTIFS(EpistaticInteractions!C2:C999, A8) -> 0 | Q8: =IF(E8 > 0, N8 / E8, 0) -> 0.027777778 | R8: =O8 * 10 + P8 * 5 + Q8 -> 10.027778 | S8: =IF(E8 <= 25, TRUE(), FALSE()) -> FALSE | T8: =IF(E8 >= 60, TRUE(), FALSE()) -> FALSE | U8: =COUNTIFS(CausalMechanisms!C2:C999, A8,CausalMechanisms!AC2:AC999, TRUE()) -> 1 | V8: =SUMIFS(CausalMechanisms!AA2:AA999,CausalMechanisms!C2:C999, A8,CausalMechanisms!AC2:AC999, TRUE()) -> 0.85833333 | W8: =COUNTIFS(CausalMechanisms!C2:C999, A8,CausalMechanisms!AD2:AD999, TRUE()) -> 1 | X8: =_xlfn.MAXIFS(ClinicalPhenotypes!G2:G999,ClinicalPhenotypes!C2:C999, A8) -> 6 | Y8: =COUNTIFS(ClinicalPhenotypes!C2:C999, A8,ClinicalPhenotypes!N2:N999, TRUE()) -> 0 | Z8: =IF(Y8 >= 1, TRUE(), FALSE()) -> FALSE | AA8: =COUNTIFS(Treatments!C2:C999, A8,Treatments!P2:P999, TRUE()) -> 1 | AB8: =IF(AA8 >= 1, TRUE(), FALSE()) -> TRUE | AL8: Grace Lin, a 36-year-old woman of Indigenous American ancestry — again an ancestry HELD OUT of the training set — presents with plaque psoriasis and asymmetric oligoarthritis concerning for psoriatic-arthritis (PsA) onset. Genotyping finds the IL23R regulatory variant rs11209026 at an allele frequency of 0.009 (rare), with allele-specific expression present. The IL23R -> IL-17 axis -> PsA-risk edge is well supported: a cis-eQTL in blood RNA-seq with effect 0.96 (SE 0.20), a caQTL in blood ATAC-seq with effect 0.88 (SE 0.21), and a pQTL in blood proteomics with effect 0.69 (SE 0.20), across two modalities and adjusted for ancestry PCs and batch. The IL-17 target is druggable (secukinumab). Two ancestry-permutation controls collapse to the null (permutation effect 0.007 and 0.019 inside +/-0.1), and reliability bins carry coverage of 30-36 per bin. Crucially — and unlike Faisal — this edge was MEASURED to replicate ACROSS ancestries: positive in a European cohort (p=0.004), positive in an East Asian cohort (p=0.012), and positive in an Indigenous American cohort (p=0.029). Because the mechanism demonstrably holds in ancestries other than the held-out one, the prediction transports. No cryptic-relatedness leakage was flagged. | AM8: =COUNTIFS(SerologyObservations!B2:B999, A8) -> 2 | AN8: =COUNTIFS(SerologyObservations!B2:B999, A8,SerologyObservations!Q2:Q999, TRUE()) -> 0 | AO8: =IF(AN8>=1,TRUE(),FALSE()) -> FALSE | AP8: =IF(AN8>=2,2,IF(AN8>=1,1,0)) -> 0 | AQ8: =_xlfn.MAXIFS(SerologyObservations!X2:X999,SerologyObservations!B2:B999, A8) -> 0 | AR8: =_xlfn.MAXIFS(SerologyObservations!V2:V999,SerologyObservations!B2:B999, A8) -> 0 | AS8: =IF(AQ8>=5,"BiopsyIndicated",IF(AQ8>=4,"RenalFlareRisk",IF(AQ8>=3,"EarlyNephritis",IF(AQ8>=2,"SerologicActive","PresymptomaticAutoimmunity")))) -> PresymptomaticAutoimmunity | AT8: =IF(AR8>=12,"High / flare",IF(AR8>=6,"Moderate",IF(AR8>=1,"Mild","Quiescent"))) -> Quiescent | AU8: =IF(AR8>=12,TRUE(),FALSE()) -> FALSE | AV8: =IF(OR(AS8="EarlyNephritis",AS8="RenalFlareRisk",AS8="BiopsyIndicated"),TRUE(),FALSE()) -> FALSE | AW8: =_xlfn.MAXIFS(CausalMechanisms!H2:H999,CausalMechanisms!C2:C999, A8) -> 4 | AX8: =IF(AW8=1,"type-I-IFN",IF(AW8=2,"B-cell/autoantibody",IF(AW8=3,"T-cell-costim",IF(AW8=4,"IL-17/23","")))) -> IL-17/23 | AY8: ="lupus-nephritis-progression--" & LOWER(AS8) -> lupus-nephritis-progression--presymptomaticautoimmunity | AZ8: =INDEX(MachineStates!Q2:Q999, MATCH(AY8,MachineStates!A2:A999, 0)) -> #VALUE!
A9: ind-h-yamamoto | B9: Hana | C9: Yamamoto | D9: East Asian | E9: 33 | F9: FALSE | H9: 45839 | I9: FALSE | J9: =B9 & " " & C9 -> Hana Yamamoto | K9: =SUBSTITUTE(LOWER(C9 & "-" & B9), " ", "-") -> yamamoto-hana | L9: ="/intake/new-patient/" & K9 -> /intake/new-patient/yamamoto-hana | M9: =IF(G9 = "", "", INDEX(FederatedDatasets!B2:B999, MATCH(G9,FederatedDatasets!A2:A999, 0))) | N9: =COUNTIFS(GenomicVariants!C2:C999, A9) -> 1 | O9: =COUNTIFS(CausalMechanisms!C2:C999, A9) -> 1 | P9: =COUNTIFS(EpistaticInteractions!C2:C999, A9) -> 0 | Q9: =IF(E9 > 0, N9 / E9, 0) -> 0.03030303 | R9: =O9 * 10 + P9 * 5 + Q9 -> 10.030303 | S9: =IF(E9 <= 25, TRUE(), FALSE()) -> FALSE | T9: =IF(E9 >= 60, TRUE(), FALSE()) -> FALSE | U9: =COUNTIFS(CausalMechanisms!C2:C999, A9,CausalMechanisms!AC2:AC999, TRUE()) -> 1 | V9: =SUMIFS(CausalMechanisms!AA2:AA999,CausalMechanisms!C2:C999, A9,CausalMechanisms!AC2:AC999, TRUE()) -> 0.75833333 | W9: =COUNTIFS(CausalMechanisms!C2:C999, A9,CausalMechanisms!AD2:AD999, TRUE()) -> 1 | X9: =_xlfn.MAXIFS(ClinicalPhenotypes!G2:G999,ClinicalPhenotypes!C2:C999, A9) -> 9 | Y9: =COUNTIFS(ClinicalPhenotypes!C2:C999, A9,ClinicalPhenotypes!N2:N999, TRUE()) -> 1 | Z9: =IF(Y9 >= 1, TRUE(), FALSE()) -> TRUE | AA9: =COUNTIFS(Treatments!C2:C999, A9,Treatments!P2:P999, TRUE()) -> 1 | AB9: =IF(AA9 >= 1, TRUE(), FALSE()) -> TRUE | AL9: 33yo East Asian woman; rising anti-dsDNA with falling complement and new significant proteinuria (0.7 g/day) over one quarter — early lupus nephritis. Progression-demo case (no v1 keystone mechanism attached). | AM9: =COUNTIFS(SerologyObservations!B2:B999, A9) -> 2 | AN9: =COUNTIFS(SerologyObservations!B2:B999, A9,SerologyObservations!Q2:Q999, TRUE()) -> 0 | AO9: =IF(AN9>=1,TRUE(),FALSE()) -> FALSE | AP9: =IF(AN9>=2,2,IF(AN9>=1,1,0)) -> 0 | AQ9: =_xlfn.MAXIFS(SerologyObservations!X2:X999,SerologyObservations!B2:B999, A9) -> 3 | AR9: =_xlfn.MAXIFS(SerologyObservations!V2:V999,SerologyObservations!B2:B999, A9) -> 0 | AS9: =IF(AQ9>=5,"BiopsyIndicated",IF(AQ9>=4,"RenalFlareRisk",IF(AQ9>=3,"EarlyNephritis",IF(AQ9>=2,"SerologicActive","PresymptomaticAutoimmunity")))) -> EarlyNephritis | AT9: =IF(AR9>=12,"High / flare",IF(AR9>=6,"Moderate",IF(AR9>=1,"Mild","Quiescent"))) -> Quiescent | AU9: =IF(AR9>=12,TRUE(),FALSE()) -> FALSE | AV9: =IF(OR(AS9="EarlyNephritis",AS9="RenalFlareRisk",AS9="BiopsyIndicated"),TRUE(),FALSE()) -> TRUE | AW9: =_xlfn.MAXIFS(CausalMechanisms!H2:H999,CausalMechanisms!C2:C999, A9) -> 1 | AX9: =IF(AW9=1,"type-I-IFN",IF(AW9=2,"B-cell/autoantibody",IF(AW9=3,"T-cell-costim",IF(AW9=4,"IL-17/23","")))) -> type-I-IFN | AY9: ="lupus-nephritis-progression--" & LOWER(AS9) -> lupus-nephritis-progression--earlynephritis | AZ9: =INDEX(MachineStates!Q2:Q999, MATCH(AY9,MachineStates!A2:A999, 0)) -> #VALUE!
A10: ind-i-conteh | B10: Ibrahim | C10: Conteh | D10: African | E10: 45 | F10: FALSE | H10: 45809 | I10: TRUE | J10: =B10 & " " & C10 -> Ibrahim Conteh | K10: =SUBSTITUTE(LOWER(C10 & "-" & B10), " ", "-") -> conteh-ibrahim | L10: ="/intake/new-patient/" & K10 -> /intake/new-patient/conteh-ibrahim | M10: =IF(G10 = "", "", INDEX(FederatedDatasets!B2:B999, MATCH(G10,FederatedDatasets!A2:A999, 0))) | N10: =COUNTIFS(GenomicVariants!C2:C999, A10) -> 1 | O10: =COUNTIFS(CausalMechanisms!C2:C999, A10) -> 1 | P10: =COUNTIFS(EpistaticInteractions!C2:C999, A10) -> 0 | Q10: =IF(E10 > 0, N10 / E10, 0) -> 0.022222222 | R10: =O10 * 10 + P10 * 5 + Q10 -> 10.022222 | S10: =IF(E10 <= 25, TRUE(), FALSE()) -> FALSE | T10: =IF(E10 >= 60, TRUE(), FALSE()) -> FALSE | U10: =COUNTIFS(CausalMechanisms!C2:C999, A10,CausalMechanisms!AC2:AC999, TRUE()) -> 1 | V10: =SUMIFS(CausalMechanisms!AA2:AA999,CausalMechanisms!C2:C999, A10,CausalMechanisms!AC2:AC999, TRUE()) -> 0.75833333 | W10: =COUNTIFS(CausalMechanisms!C2:C999, A10,CausalMechanisms!AD2:AD999, TRUE()) -> 1 | X10: =_xlfn.MAXIFS(ClinicalPhenotypes!G2:G999,ClinicalPhenotypes!C2:C999, A10) -> 8 | Y10: =COUNTIFS(ClinicalPhenotypes!C2:C999, A10,ClinicalPhenotypes!N2:N999, TRUE()) -> 1 | Z10: =IF(Y10 >= 1, TRUE(), FALSE()) -> TRUE | AA10: =COUNTIFS(Treatments!C2:C999, A10,Treatments!P2:P999, TRUE()) -> 0 | AB10: =IF(AA10 >= 1, TRUE(), FALSE()) -> FALSE | AL10: 45yo African man; brisk serologic activity and proteinuria climbing to 1.5 g/day — at risk of renal flare. Progression-demo case (no v1 keystone mechanism attached). | AM10: =COUNTIFS(SerologyObservations!B2:B999, A10) -> 2 | AN10: =COUNTIFS(SerologyObservations!B2:B999, A10,SerologyObservations!Q2:Q999, TRUE()) -> 0 | AO10: =IF(AN10>=1,TRUE(),FALSE()) -> FALSE | AP10: =IF(AN10>=2,2,IF(AN10>=1,1,0)) -> 0 | AQ10: =_xlfn.MAXIFS(SerologyObservations!X2:X999,SerologyObservations!B2:B999, A10) -> 4 | AR10: =_xlfn.MAXIFS(SerologyObservations!V2:V999,SerologyObservations!B2:B999, A10) -> 0 | AS10: =IF(AQ10>=5,"BiopsyIndicated",IF(AQ10>=4,"RenalFlareRisk",IF(AQ10>=3,"EarlyNephritis",IF(AQ10>=2,"SerologicActive","PresymptomaticAutoimmunity")))) -> RenalFlareRisk | AT10: =IF(AR10>=12,"High / flare",IF(AR10>=6,"Moderate",IF(AR10>=1,"Mild","Quiescent"))) -> Quiescent | AU10: =IF(AR10>=12,TRUE(),FALSE()) -> FALSE | AV10: =IF(OR(AS10="EarlyNephritis",AS10="RenalFlareRisk",AS10="BiopsyIndicated"),TRUE(),FALSE()) -> TRUE | AW10: =_xlfn.MAXIFS(CausalMechanisms!H2:H999,CausalMechanisms!C2:C999, A10) -> 2 | AX10: =IF(AW10=1,"type-I-IFN",IF(AW10=2,"B-cell/autoantibody",IF(AW10=3,"T-cell-costim",IF(AW10=4,"IL-17/23","")))) -> B-cell/autoantibody | AY10: ="lupus-nephritis-progression--" & LOWER(AS10) -> lupus-nephritis-progression--renalflarerisk | AZ10: =INDEX(MachineStates!Q2:Q999, MATCH(AY10,MachineStates!A2:A999, 0)) -> #VALUE!
A11: ind-j-brooks | B11: Jamal | C11: Brooks | D11: Hispanic/Latino | E11: 52 | F11: FALSE | G11: fed-europe | H11: 45058 | I11: FALSE | J11: =B11 & " " & C11 -> Jamal Brooks | K11: =SUBSTITUTE(LOWER(C11 & "-" & B11), " ", "-") -> brooks-jamal | L11: ="/intake/new-patient/" & K11 -> /intake/new-patient/brooks-jamal | M11: =IF(G11 = "", "", INDEX(FederatedDatasets!B2:B999, MATCH(G11,FederatedDatasets!A2:A999, 0))) -> European Reference Node | N11: =COUNTIFS(GenomicVariants!C2:C999, A11) -> 1 | O11: =COUNTIFS(CausalMechanisms!C2:C999, A11) -> 1 | P11: =COUNTIFS(EpistaticInteractions!C2:C999, A11) -> 0 | Q11: =IF(E11 > 0, N11 / E11, 0) -> 0.019230769 | R11: =O11 * 10 + P11 * 5 + Q11 -> 10.019231 | S11: =IF(E11 <= 25, TRUE(), FALSE()) -> FALSE | T11: =IF(E11 >= 60, TRUE(), FALSE()) -> FALSE | U11: =COUNTIFS(CausalMechanisms!C2:C999, A11,CausalMechanisms!AC2:AC999, TRUE()) -> 1 | V11: =SUMIFS(CausalMechanisms!AA2:AA999,CausalMechanisms!C2:C999, A11,CausalMechanisms!AC2:AC999, TRUE()) -> 0.75833333 | W11: =COUNTIFS(CausalMechanisms!C2:C999, A11,CausalMechanisms!AD2:AD999, TRUE()) -> 1 | X11: =_xlfn.MAXIFS(ClinicalPhenotypes!G2:G999,ClinicalPhenotypes!C2:C999, A11) -> 8 | Y11: =COUNTIFS(ClinicalPhenotypes!C2:C999, A11,ClinicalPhenotypes!N2:N999, TRUE()) -> 1 | Z11: =IF(Y11 >= 1, TRUE(), FALSE()) -> TRUE | AA11: =COUNTIFS(Treatments!C2:C999, A11,Treatments!P2:P999, TRUE()) -> 1 | AB11: =IF(AA11 >= 1, TRUE(), FALSE()) -> TRUE | AL11: 52yo Hispanic/Latino man; the targeted mechanism is confirmed but the calibration bins are under-covered — uncertainty collapses, so NOT actionable on the calibration gate. | AM11: =COUNTIFS(SerologyObservations!B2:B999, A11) -> 2 | AN11: =COUNTIFS(SerologyObservations!B2:B999, A11,SerologyObservations!Q2:Q999, TRUE()) -> 0 | AO11: =IF(AN11>=1,TRUE(),FALSE()) -> FALSE | AP11: =IF(AN11>=2,2,IF(AN11>=1,1,0)) -> 0 | AQ11: =_xlfn.MAXIFS(SerologyObservations!X2:X999,SerologyObservations!B2:B999, A11) -> 0 | AR11: =_xlfn.MAXIFS(SerologyObservations!V2:V999,SerologyObservations!B2:B999, A11) -> 0 | AS11: =IF(AQ11>=5,"BiopsyIndicated",IF(AQ11>=4,"RenalFlareRisk",IF(AQ11>=3,"EarlyNephritis",IF(AQ11>=2,"SerologicActive","PresymptomaticAutoimmunity")))) -> PresymptomaticAutoimmunity | AT11: =IF(AR11>=12,"High / flare",IF(AR11>=6,"Moderate",IF(AR11>=1,"Mild","Quiescent"))) -> Quiescent | AU11: =IF(AR11>=12,TRUE(),FALSE()) -> FALSE | AV11: =IF(OR(AS11="EarlyNephritis",AS11="RenalFlareRisk",AS11="BiopsyIndicated"),TRUE(),FALSE()) -> FALSE | AW11: =_xlfn.MAXIFS(CausalMechanisms!H2:H999,CausalMechanisms!C2:C999, A11) -> 1 | AX11: =IF(AW11=1,"type-I-IFN",IF(AW11=2,"B-cell/autoantibody",IF(AW11=3,"T-cell-costim",IF(AW11=4,"IL-17/23","")))) -> type-I-IFN | AY11: ="lupus-nephritis-progression--" & LOWER(AS11) -> lupus-nephritis-progression--presymptomaticautoimmunity | AZ11: =INDEX(MachineStates!Q2:Q999, MATCH(AY11,MachineStates!A2:A999, 0)) -> #VALUE!
A12: ind-k-nair | B12: Kavya | C12: Nair | D12: South Asian | E12: 39 | F12: TRUE | G12: fed-amazon | H12: 45689 | I12: FALSE | J12: =B12 & " " & C12 -> Kavya Nair | K12: =SUBSTITUTE(LOWER(C12 & "-" & B12), " ", "-") -> nair-kavya | L12: ="/intake/new-patient/" & K12 -> /intake/new-patient/nair-kavya | M12: =IF(G12 = "", "", INDEX(FederatedDatasets!B2:B999, MATCH(G12,FederatedDatasets!A2:A999, 0))) -> Amazon Indigenous Cohort | N12: =COUNTIFS(GenomicVariants!C2:C999, A12) -> 1 | O12: =COUNTIFS(CausalMechanisms!C2:C999, A12) -> 1 | P12: =COUNTIFS(EpistaticInteractions!C2:C999, A12) -> 0 | Q12: =IF(E12 > 0, N12 / E12, 0) -> 0.025641026 | R12: =O12 * 10 + P12 * 5 + Q12 -> 10.025641 | S12: =IF(E12 <= 25, TRUE(), FALSE()) -> FALSE | T12: =IF(E12 >= 60, TRUE(), FALSE()) -> FALSE | U12: =COUNTIFS(CausalMechanisms!C2:C999, A12,CausalMechanisms!AC2:AC999, TRUE()) -> 1 | V12: =SUMIFS(CausalMechanisms!AA2:AA999,CausalMechanisms!C2:C999, A12,CausalMechanisms!AC2:AC999, TRUE()) -> 0.85833333 | W12: =COUNTIFS(CausalMechanisms!C2:C999, A12,CausalMechanisms!AD2:AD999, TRUE()) -> 0 | X12: =_xlfn.MAXIFS(ClinicalPhenotypes!G2:G999,ClinicalPhenotypes!C2:C999, A12) -> 2 | Y12: =COUNTIFS(ClinicalPhenotypes!C2:C999, A12,ClinicalPhenotypes!N2:N999, TRUE()) -> 0 | Z12: =IF(Y12 >= 1, TRUE(), FALSE()) -> FALSE | AA12: =COUNTIFS(Treatments!C2:C999, A12,Treatments!P2:P999, TRUE()) -> 0 | AB12: =IF(AA12 >= 1, TRUE(), FALSE()) -> FALSE | AL12: 39yo South Asian woman, ancestry absent from training; confirmed mechanism but all replications ran in one ancestry — fails ancestry transport, NOT actionable. | AM12: =COUNTIFS(SerologyObservations!B2:B999, A12) -> 2 | AN12: =COUNTIFS(SerologyObservations!B2:B999, A12,SerologyObservations!Q2:Q999, TRUE()) -> 0 | AO12: =IF(AN12>=1,TRUE(),FALSE()) -> FALSE | AP12: =IF(AN12>=2,2,IF(AN12>=1,1,0)) -> 0 | AQ12: =_xlfn.MAXIFS(SerologyObservations!X2:X999,SerologyObservations!B2:B999, A12) -> 0 | AR12: =_xlfn.MAXIFS(SerologyObservations!V2:V999,SerologyObservations!B2:B999, A12) -> 0 | AS12: =IF(AQ12>=5,"BiopsyIndicated",IF(AQ12>=4,"RenalFlareRisk",IF(AQ12>=3,"EarlyNephritis",IF(AQ12>=2,"SerologicActive","PresymptomaticAutoimmunity")))) -> PresymptomaticAutoimmunity | AT12: =IF(AR12>=12,"High / flare",IF(AR12>=6,"Moderate",IF(AR12>=1,"Mild","Quiescent"))) -> Quiescent | AU12: =IF(AR12>=12,TRUE(),FALSE()) -> FALSE | AV12: =IF(OR(AS12="EarlyNephritis",AS12="RenalFlareRisk",AS12="BiopsyIndicated"),TRUE(),FALSE()) -> FALSE | AW12: =_xlfn.MAXIFS(CausalMechanisms!H2:H999,CausalMechanisms!C2:C999, A12) -> 4 | AX12: =IF(AW12=1,"type-I-IFN",IF(AW12=2,"B-cell/autoantibody",IF(AW12=3,"T-cell-costim",IF(AW12=4,"IL-17/23","")))) -> IL-17/23 | AY12: ="lupus-nephritis-progression--" & LOWER(AS12) -> lupus-nephritis-progression--presymptomaticautoimmunity | AZ12: =INDEX(MachineStates!Q2:Q999, MATCH(AY12,MachineStates!A2:A999, 0)) -> #VALUE!
A13: ind-l-brandt | B13: Lena | C13: Brandt | D13: Indigenous American | E13: 28 | F13: TRUE | G13: fed-amazon | H13: 45691 | I13: FALSE | J13: =B13 & " " & C13 -> Lena Brandt | K13: =SUBSTITUTE(LOWER(C13 & "-" & B13), " ", "-") -> brandt-lena | L13: ="/intake/new-patient/" & K13 -> /intake/new-patient/brandt-lena | M13: =IF(G13 = "", "", INDEX(FederatedDatasets!B2:B999, MATCH(G13,FederatedDatasets!A2:A999, 0))) -> Amazon Indigenous Cohort | N13: =COUNTIFS(GenomicVariants!C2:C999, A13) -> 1 | O13: =COUNTIFS(CausalMechanisms!C2:C999, A13) -> 1 | P13: =COUNTIFS(EpistaticInteractions!C2:C999, A13) -> 0 | Q13: =IF(E13 > 0, N13 / E13, 0) -> 0.035714286 | R13: =O13 * 10 + P13 * 5 + Q13 -> 10.035714 | S13: =IF(E13 <= 25, TRUE(), FALSE()) -> FALSE | T13: =IF(E13 >= 60, TRUE(), FALSE()) -> FALSE | U13: =COUNTIFS(CausalMechanisms!C2:C999, A13,CausalMechanisms!AC2:AC999, TRUE()) -> 1 | V13: =SUMIFS(CausalMechanisms!AA2:AA999,CausalMechanisms!C2:C999, A13,CausalMechanisms!AC2:AC999, TRUE()) -> 0.85833333 | W13: =COUNTIFS(CausalMechanisms!C2:C999, A13,CausalMechanisms!AD2:AD999, TRUE()) -> 1 | X13: =_xlfn.MAXIFS(ClinicalPhenotypes!G2:G999,ClinicalPhenotypes!C2:C999, A13) -> 6 | Y13: =COUNTIFS(ClinicalPhenotypes!C2:C999, A13,ClinicalPhenotypes!N2:N999, TRUE()) -> 0 | Z13: =IF(Y13 >= 1, TRUE(), FALSE()) -> FALSE | AA13: =COUNTIFS(Treatments!C2:C999, A13,Treatments!P2:P999, TRUE()) -> 1 | AB13: =IF(AA13 >= 1, TRUE(), FALSE()) -> TRUE | AL13: 28yo Indigenous-American woman, holdout ancestry; the positive twin — the IL23R node replicated cross-ancestry, so transport passes and she is actionable. | AM13: =COUNTIFS(SerologyObservations!B2:B999, A13) -> 2 | AN13: =COUNTIFS(SerologyObservations!B2:B999, A13,SerologyObservations!Q2:Q999, TRUE()) -> 0 | AO13: =IF(AN13>=1,TRUE(),FALSE()) -> FALSE | AP13: =IF(AN13>=2,2,IF(AN13>=1,1,0)) -> 0 | AQ13: =_xlfn.MAXIFS(SerologyObservations!X2:X999,SerologyObservations!B2:B999, A13) -> 0 | AR13: =_xlfn.MAXIFS(SerologyObservations!V2:V999,SerologyObservations!B2:B999, A13) -> 0 | AS13: =IF(AQ13>=5,"BiopsyIndicated",IF(AQ13>=4,"RenalFlareRisk",IF(AQ13>=3,"EarlyNephritis",IF(AQ13>=2,"SerologicActive","PresymptomaticAutoimmunity")))) -> PresymptomaticAutoimmunity | AT13: =IF(AR13>=12,"High / flare",IF(AR13>=6,"Moderate",IF(AR13>=1,"Mild","Quiescent"))) -> Quiescent | AU13: =IF(AR13>=12,TRUE(),FALSE()) -> FALSE | AV13: =IF(OR(AS13="EarlyNephritis",AS13="RenalFlareRisk",AS13="BiopsyIndicated"),TRUE(),FALSE()) -> FALSE | AW13: =_xlfn.MAXIFS(CausalMechanisms!H2:H999,CausalMechanisms!C2:C999, A13) -> 4 | AX13: =IF(AW13=1,"type-I-IFN",IF(AW13=2,"B-cell/autoantibody",IF(AW13=3,"T-cell-costim",IF(AW13=4,"IL-17/23","")))) -> IL-17/23 | AY13: ="lupus-nephritis-progression--" & LOWER(AS13) -> lupus-nephritis-progression--presymptomaticautoimmunity | AZ13: =INDEX(MachineStates!Q2:Q999, MATCH(AY13,MachineStates!A2:A999, 0)) -> #VALUE!

Sheet GenomicVariants
A1: GenomicVariantId | B1: VariantLabel | C1: Individual | D1: VariantType | E1: AlleleFrequency | F1: HasAlleleSpecificExpression | G1: Name | H1: ParentPath | I1: RelativePath | J1: VariantTypeLabel | K1: VariantClassIsRare | L1: IndividualAncestryLabel | M1: IsRareVariant | N1: IsCausalCandidate | O1: SourceQuote
A2: var-a-irf5 | B2: IRF5 regulatory (rs2004640) | C2: ind-a-reyes | D2: regulatory | E2: 0.006 | F2: TRUE | G2: =B2 -> IRF5 regulatory (rs2004640) | H2: =INDEX(Individuals!L2:L999, MATCH(C2,Individuals!A2:A999, 0)) -> /intake/new-patient/reyes-ana | I2: =H2 & "/variants/" & A2 -> /intake/new-patient/reyes-ana/variants/var-a-irf5 | J2: =INDEX(VariantTypes!B2:B999, MATCH(D2,VariantTypes!A2:A999, 0)) -> Regulatory Variant | K2: =INDEX(VariantTypes!C2:C999, MATCH(D2,VariantTypes!A2:A999, 0)) -> TRUE | L2: =INDEX(Individuals!D2:D999, MATCH(C2,Individuals!A2:A999, 0)) -> European | M2: =IF(E2 < 0.01, TRUE(), FALSE()) -> TRUE | N2: =IF(AND(OR(M2, K2), F2), TRUE(), FALSE()) -> TRUE | O2: IRF5 regulatory variant rs2004640 at an allele frequency of 0.006 (rare), and allele-specific expression is present
A3: var-b-irf5 | B3: IRF5 regulatory (rs2004640) | C3: ind-b-okafor | D3: regulatory | E3: 0.006 | F3: TRUE | G3: =B3 -> IRF5 regulatory (rs2004640) | H3: =INDEX(Individuals!L2:L999, MATCH(C3,Individuals!A2:A999, 0)) -> /intake/new-patient/okafor-bili | I3: =H3 & "/variants/" & A3 -> /intake/new-patient/okafor-bili/variants/var-b-irf5 | J3: =INDEX(VariantTypes!B2:B999, MATCH(D3,VariantTypes!A2:A999, 0)) -> Regulatory Variant | K3: =INDEX(VariantTypes!C2:C999, MATCH(D3,VariantTypes!A2:A999, 0)) -> TRUE | L3: =INDEX(Individuals!D2:D999, MATCH(C3,Individuals!A2:A999, 0)) -> European | M3: =IF(E3 < 0.01, TRUE(), FALSE()) -> TRUE | N3: =IF(AND(OR(M3, K3), F3), TRUE(), FALSE()) -> TRUE | O3: IRF5 regulatory variant rs2004640 at an allele frequency of 0.006 (rare), with allele-specific expression present
A4: var-c-stat4 | B4: STAT4 regulatory (rs7574865) | C4: ind-c-chen | D4: regulatory | E4: 0.008 | F4: TRUE | G4: =B4 -> STAT4 regulatory (rs7574865) | H4: =INDEX(Individuals!L2:L999, MATCH(C4,Individuals!A2:A999, 0)) -> /intake/new-patient/wei-chen | I4: =H4 & "/variants/" & A4 -> /intake/new-patient/wei-chen/variants/var-c-stat4 | J4: =INDEX(VariantTypes!B2:B999, MATCH(D4,VariantTypes!A2:A999, 0)) -> Regulatory Variant | K4: =INDEX(VariantTypes!C2:C999, MATCH(D4,VariantTypes!A2:A999, 0)) -> TRUE | L4: =INDEX(Individuals!D2:D999, MATCH(C4,Individuals!A2:A999, 0)) -> East Asian | M4: =IF(E4 < 0.01, TRUE(), FALSE()) -> TRUE | N4: =IF(AND(OR(M4, K4), F4), TRUE(), FALSE()) -> TRUE | O4: STAT4 regulatory variant rs7574865 at an allele frequency of 0.008 (rare), with allele-specific expression present
A5: var-d-irf5 | B5: IRF5 regulatory (rs2004640) | C5: ind-d-santos | D5: regulatory | E5: 0.006 | F5: TRUE | G5: =B5 -> IRF5 regulatory (rs2004640) | H5: =INDEX(Individuals!L2:L999, MATCH(C5,Individuals!A2:A999, 0)) -> /intake/new-patient/santos-diego | I5: =H5 & "/variants/" & A5 -> /intake/new-patient/santos-diego/variants/var-d-irf5 | J5: =INDEX(VariantTypes!B2:B999, MATCH(D5,VariantTypes!A2:A999, 0)) -> Regulatory Variant | K5: =INDEX(VariantTypes!C2:C999, MATCH(D5,VariantTypes!A2:A999, 0)) -> TRUE | L5: =INDEX(Individuals!D2:D999, MATCH(C5,Individuals!A2:A999, 0)) -> European | M5: =IF(E5 < 0.01, TRUE(), FALSE()) -> TRUE | N5: =IF(AND(OR(M5, K5), F5), TRUE(), FALSE()) -> TRUE | O5: IRF5 regulatory variant rs2004640 at an allele frequency of 0.006 (rare), with allele-specific expression present
A6: var-e-ctla4 | B6: CTLA4 enhancer (rs3087243) | C6: ind-e-mensah | D6: regulatory | E6: 0.007 | F6: TRUE | G6: =B6 -> CTLA4 enhancer (rs3087243) | H6: =INDEX(Individuals!L2:L999, MATCH(C6,Individuals!A2:A999, 0)) -> /intake/new-patient/mensah-esi | I6: =H6 & "/variants/" & A6 -> /intake/new-patient/mensah-esi/variants/var-e-ctla4 | J6: =INDEX(VariantTypes!B2:B999, MATCH(D6,VariantTypes!A2:A999, 0)) -> Regulatory Variant | K6: =INDEX(VariantTypes!C2:C999, MATCH(D6,VariantTypes!A2:A999, 0)) -> TRUE | L6: =INDEX(Individuals!D2:D999, MATCH(C6,Individuals!A2:A999, 0)) -> African | M6: =IF(E6 < 0.01, TRUE(), FALSE()) -> TRUE | N6: =IF(AND(OR(M6, K6), F6), TRUE(), FALSE()) -> TRUE | O6: CTLA4 enhancer variant rs3087243 at an allele frequency of 0.007 (rare), with allele-specific expression present
A7: var-f-il23r | B7: IL23R regulatory (rs11209026) | C7: ind-f-haidar | D7: regulatory | E7: 0.009 | F7: TRUE | G7: =B7 -> IL23R regulatory (rs11209026) | H7: =INDEX(Individuals!L2:L999, MATCH(C7,Individuals!A2:A999, 0)) -> /intake/new-patient/haidar-faisal | I7: =H7 & "/variants/" & A7 -> /intake/new-patient/haidar-faisal/variants/var-f-il23r | J7: =INDEX(VariantTypes!B2:B999, MATCH(D7,VariantTypes!A2:A999, 0)) -> Regulatory Variant | K7: =INDEX(VariantTypes!C2:C999, MATCH(D7,VariantTypes!A2:A999, 0)) -> TRUE | L7: =INDEX(Individuals!D2:D999, MATCH(C7,Individuals!A2:A999, 0)) -> Indigenous American | M7: =IF(E7 < 0.01, TRUE(), FALSE()) -> TRUE | N7: =IF(AND(OR(M7, K7), F7), TRUE(), FALSE()) -> TRUE | O7: IL23R regulatory variant rs11209026 at an allele frequency of 0.009 (rare), with allele-specific expression present
A8: var-g-il23r | B8: IL23R regulatory (rs11209026) | C8: ind-g-lin | D8: regulatory | E8: 0.009 | F8: TRUE | G8: =B8 -> IL23R regulatory (rs11209026) | H8: =INDEX(Individuals!L2:L999, MATCH(C8,Individuals!A2:A999, 0)) -> /intake/new-patient/lin-grace | I8: =H8 & "/variants/" & A8 -> /intake/new-patient/lin-grace/variants/var-g-il23r | J8: =INDEX(VariantTypes!B2:B999, MATCH(D8,VariantTypes!A2:A999, 0)) -> Regulatory Variant | K8: =INDEX(VariantTypes!C2:C999, MATCH(D8,VariantTypes!A2:A999, 0)) -> TRUE | L8: =INDEX(Individuals!D2:D999, MATCH(C8,Individuals!A2:A999, 0)) -> Indigenous American | M8: =IF(E8 < 0.01, TRUE(), FALSE()) -> TRUE | N8: =IF(AND(OR(M8, K8), F8), TRUE(), FALSE()) -> TRUE | O8: IL23R regulatory variant rs11209026 at an allele frequency of 0.009 (rare), with allele-specific expression present
A9: var-h-irf5 | B9: IRF5 regulatory (rs2004640) | C9: ind-h-yamamoto | D9: regulatory | E9: 0.006 | F9: TRUE | G9: =B9 -> IRF5 regulatory (rs2004640) | H9: =INDEX(Individuals!L2:L999, MATCH(C9,Individuals!A2:A999, 0)) -> /intake/new-patient/yamamoto-hana | I9: =H9 & "/variants/" & A9 -> /intake/new-patient/yamamoto-hana/variants/var-h-irf5 | J9: =INDEX(VariantTypes!B2:B999, MATCH(D9,VariantTypes!A2:A999, 0)) -> Regulatory Variant | K9: =INDEX(VariantTypes!C2:C999, MATCH(D9,VariantTypes!A2:A999, 0)) -> TRUE | L9: =INDEX(Individuals!D2:D999, MATCH(C9,Individuals!A2:A999, 0)) -> East Asian | M9: =IF(E9 < 0.01, TRUE(), FALSE()) -> TRUE | N9: =IF(AND(OR(M9, K9), F9), TRUE(), FALSE()) -> TRUE | O9: IRF5 regulatory variant rs2004640 at an allele frequency of 0.006 (rare), and allele-specific expression is present
A10: var-i-irf5 | B10: IRF5 regulatory (rs2004640) | C10: ind-i-conteh | D10: regulatory | E10: 0.006 | F10: TRUE | G10: =B10 -> IRF5 regulatory (rs2004640) | H10: =INDEX(Individuals!L2:L999, MATCH(C10,Individuals!A2:A999, 0)) -> /intake/new-patient/conteh-ibrahim | I10: =H10 & "/variants/" & A10 -> /intake/new-patient/conteh-ibrahim/variants/var-i-irf5 | J10: =INDEX(VariantTypes!B2:B999, MATCH(D10,VariantTypes!A2:A999, 0)) -> Regulatory Variant | K10: =INDEX(VariantTypes!C2:C999, MATCH(D10,VariantTypes!A2:A999, 0)) -> TRUE | L10: =INDEX(Individuals!D2:D999, MATCH(C10,Individuals!A2:A999, 0)) -> African | M10: =IF(E10 < 0.01, TRUE(), FALSE()) -> TRUE | N10: =IF(AND(OR(M10, K10), F10), TRUE(), FALSE()) -> TRUE | O10: IRF5 regulatory variant rs2004640 at an allele frequency of 0.006 (rare), with allele-specific expression present
A11: var-j-irf5 | B11: IRF5 regulatory (rs2004640) | C11: ind-j-brooks | D11: regulatory | E11: 0.006 | F11: TRUE | G11: =B11 -> IRF5 regulatory (rs2004640) | H11: =INDEX(Individuals!L2:L999, MATCH(C11,Individuals!A2:A999, 0)) -> /intake/new-patient/brooks-jamal | I11: =H11 & "/variants/" & A11 -> /intake/new-patient/brooks-jamal/variants/var-j-irf5 | J11: =INDEX(VariantTypes!B2:B999, MATCH(D11,VariantTypes!A2:A999, 0)) -> Regulatory Variant | K11: =INDEX(VariantTypes!C2:C999, MATCH(D11,VariantTypes!A2:A999, 0)) -> TRUE | L11: =INDEX(Individuals!D2:D999, MATCH(C11,Individuals!A2:A999, 0)) -> Hispanic/Latino | M11: =IF(E11 < 0.01, TRUE(), FALSE()) -> TRUE | N11: =IF(AND(OR(M11, K11), F11), TRUE(), FALSE()) -> TRUE | O11: IRF5 regulatory variant rs2004640 at an allele frequency of 0.006 (rare), with allele-specific expression present
